2024-07-01 10:22:39,770 - ERROR - An error occurred: 'GDriveHandler' object has no attribute 'check_lock_file'
2024-07-01 10:22:48,953 - ERROR - An error occurred: 'GDriveHandler' object has no attribute 'check_lock_file'
2024-07-01 10:25:58,936 - ERROR - An error occurred: [Errno 13] Permission denied: 'test_from_gdrive.xlsx'
2024-07-01 10:41:22,870 - ERROR - An error occurred: [Errno 2] No such file or directory: 'c:\\Users\\msenthilnathan\\chatGPT-GUI\\Nool 2.0\\data\\data/status.xlsx'
2024-07-01 10:48:16,803 - ERROR - An error occurred: [Errno 13] Permission denied: 'test_from_gdrive.xlsx'
2024-07-01 14:54:01,487 - ERROR - An error occurred: [Errno 13] Permission denied: 'test_from_gdrive.xlsx'
2024-07-01 14:55:26,162 - ERROR - An error occurred: [Errno 13] Permission denied: 'test_from_gdrive.xlsx'
2024-07-01 15:02:32,683 - ERROR - An error occurred: [Errno 13] Permission denied: 'test_from_gdrive.xlsx' - c:\Users\msenthilnathan\chatGPT-GUI\Nool 2.0\src\gdrive_main.py:69
2024-07-01 15:05:07,261 - ERROR - An error occurred: [Errno 13] Permission denied: 'test_from_gdrive.xlsx' - c:\Users\msenthilnathan\chatGPT-GUI\Nool 2.0\src\gdrive_main.py:69
Traceback (most recent call last):
  File "c:\Users\msenthilnathan\chatGPT-GUI\Nool 2.0\src\gdrive_main.py", line 54, in <module>
    gdrive_handler.download_file(file_id_to_download, file_name_to_download)
  File "c:\Users\msenthilnathan\chatGPT-GUI\Nool 2.0\src\gdrive_handler.py", line 98, in download_file
    file.GetContentFile(file_name)
  File "C:\Users\msenthilnathan\AppData\Local\Packages\PythonSoftwareFoundation.Python.3.12_qbz5n2kfra8p0\LocalCache\local-packages\Python312\site-packages\pydrive\files.py", line 211, in GetContentFile
    f = open(filename, 'wb')
        ^^^^^^^^^^^^^^^^^^^^
PermissionError: [Errno 13] Permission denied: 'test_from_gdrive.xlsx'
2024-07-01 15:10:12,154 - ERROR - An error occurred: [Errno 13] Permission denied: 'test_from_gdrive.xlsx' - c:\Users\msenthilnathan\chatGPT-GUI\Nool 2.0\src\gdrive_main.py:69
Traceback (most recent call last):
  File "c:\Users\msenthilnathan\chatGPT-GUI\Nool 2.0\src\gdrive_main.py", line 54, in <module>
    gdrive_handler.download_file(file_id_to_download, file_name_to_download)
  File "c:\Users\msenthilnathan\chatGPT-GUI\Nool 2.0\src\gdrive_handler.py", line 98, in download_file
    file.GetContentFile(file_name)
  File "C:\Users\msenthilnathan\AppData\Local\Packages\PythonSoftwareFoundation.Python.3.12_qbz5n2kfra8p0\LocalCache\local-packages\Python312\site-packages\pydrive\files.py", line 211, in GetContentFile
    f = open(filename, 'wb')
        ^^^^^^^^^^^^^^^^^^^^
PermissionError: [Errno 13] Permission denied: 'test_from_gdrive.xlsx'
2024-07-01 15:11:23,870 - ERROR - An error occurred: [Errno 13] Permission denied: 'test_from_gdrive.xlsx' - c:\Users\msenthilnathan\chatGPT-GUI\Nool 2.0\src\gdrive_main.py:69
Traceback (most recent call last):
  File "c:\Users\msenthilnathan\chatGPT-GUI\Nool 2.0\src\gdrive_main.py", line 54, in <module>
    gdrive_handler.download_file(file_id_to_download, file_name_to_download)
  File "c:\Users\msenthilnathan\chatGPT-GUI\Nool 2.0\src\gdrive_handler.py", line 98, in download_file
    file.GetContentFile(file_name)
  File "C:\Users\msenthilnathan\AppData\Local\Packages\PythonSoftwareFoundation.Python.3.12_qbz5n2kfra8p0\LocalCache\local-packages\Python312\site-packages\pydrive\files.py", line 211, in GetContentFile
    f = open(filename, 'wb')
        ^^^^^^^^^^^^^^^^^^^^
PermissionError: [Errno 13] Permission denied: 'test_from_gdrive.xlsx'
2024-07-01 15:17:38,770 - ERROR - An error occurred: [Errno 13] Permission denied: 'test_from_gdrive.xlsx' - c:\Users\msenthilnathan\chatGPT-GUI\Nool 2.0\src\gdrive_main.py:71
Traceback (most recent call last):
  File "c:\Users\msenthilnathan\chatGPT-GUI\Nool 2.0\src\gdrive_main.py", line 56, in <module>
    gdrive_handler.download_file(file_id_to_download, file_name_to_download)
  File "c:\Users\msenthilnathan\chatGPT-GUI\Nool 2.0\src\gdrive_handler.py", line 98, in download_file
    file.GetContentFile(file_name)
  File "C:\Users\msenthilnathan\AppData\Local\Packages\PythonSoftwareFoundation.Python.3.12_qbz5n2kfra8p0\LocalCache\local-packages\Python312\site-packages\pydrive\files.py", line 211, in GetContentFile
    f = open(filename, 'wb')
        ^^^^^^^^^^^^^^^^^^^^
PermissionError: [Errno 13] Permission denied: 'test_from_gdrive.xlsx'
2024-07-02 08:46:44,023 - ERROR - Authentication failed: <HttpError 401 when requesting https://www.googleapis.com/oauth2/v2/userinfo?alt=json returned "Request is missing required authentication credential. Expected OAuth 2 access token, login cookie or other valid authentication credential. See https://developers.google.com/identity/sign-in/web/devconsole-project.". Details: "Request is missing required authentication credential. Expected OAuth 2 access token, login cookie or other valid authentication credential. See https://developers.google.com/identity/sign-in/web/devconsole-project."> - c:\Users\msenthilnathan\chatGPT-GUI\Nool 2.0\src\gdrive_handler.py:73
2024-07-02 08:51:57,699 - ERROR - Authentication failed: <HttpError 401 when requesting https://www.googleapis.com/oauth2/v2/userinfo?alt=json returned "Request is missing required authentication credential. Expected OAuth 2 access token, login cookie or other valid authentication credential. See https://developers.google.com/identity/sign-in/web/devconsole-project.". Details: "Request is missing required authentication credential. Expected OAuth 2 access token, login cookie or other valid authentication credential. See https://developers.google.com/identity/sign-in/web/devconsole-project."> - c:\Users\msenthilnathan\chatGPT-GUI\Nool 2.0\src\gdrive_handler.py:73
2024-07-02 08:56:43,011 - ERROR - Authentication failed: <HttpError 401 when requesting https://www.googleapis.com/oauth2/v2/userinfo?alt=json returned "Request is missing required authentication credential. Expected OAuth 2 access token, login cookie or other valid authentication credential. See https://developers.google.com/identity/sign-in/web/devconsole-project.". Details: "Request is missing required authentication credential. Expected OAuth 2 access token, login cookie or other valid authentication credential. See https://developers.google.com/identity/sign-in/web/devconsole-project."> - c:\Users\msenthilnathan\chatGPT-GUI\Nool 2.0\src\gdrive_handler.py:74
2024-07-02 08:59:33,690 - ERROR - Authentication failed: <HttpError 401 when requesting https://www.googleapis.com/oauth2/v2/userinfo?alt=json returned "Request is missing required authentication credential. Expected OAuth 2 access token, login cookie or other valid authentication credential. See https://developers.google.com/identity/sign-in/web/devconsole-project.". Details: "Request is missing required authentication credential. Expected OAuth 2 access token, login cookie or other valid authentication credential. See https://developers.google.com/identity/sign-in/web/devconsole-project."> - c:\Users\msenthilnathan\chatGPT-GUI\Nool 2.0\src\gdrive_handler.py:75
2024-07-02 09:04:47,198 - ERROR - Authentication failed: <HttpError 401 when requesting https://www.googleapis.com/oauth2/v2/userinfo?alt=json returned "Request is missing required authentication credential. Expected OAuth 2 access token, login cookie or other valid authentication credential. See https://developers.google.com/identity/sign-in/web/devconsole-project.". Details: "Request is missing required authentication credential. Expected OAuth 2 access token, login cookie or other valid authentication credential. See https://developers.google.com/identity/sign-in/web/devconsole-project."> - c:\Users\msenthilnathan\chatGPT-GUI\Nool 2.0\src\gdrive_handler.py:78
2024-07-02 09:05:26,856 - ERROR - Authentication failed: <HttpError 401 when requesting https://www.googleapis.com/oauth2/v2/userinfo?alt=json returned "Request is missing required authentication credential. Expected OAuth 2 access token, login cookie or other valid authentication credential. See https://developers.google.com/identity/sign-in/web/devconsole-project.". Details: "Request is missing required authentication credential. Expected OAuth 2 access token, login cookie or other valid authentication credential. See https://developers.google.com/identity/sign-in/web/devconsole-project."> - c:\Users\msenthilnathan\chatGPT-GUI\Nool 2.0\src\gdrive_handler.py:78
2024-07-02 09:08:11,892 - ERROR - Authentication failed: The access_token is expired or invalid and can't be refreshed. - c:\Users\msenthilnathan\chatGPT-GUI\Nool 2.0\src\gdrive_handler.py:78
2024-07-02 09:08:35,723 - ERROR - Authentication failed: The access_token is expired or invalid and can't be refreshed. - c:\Users\msenthilnathan\chatGPT-GUI\Nool 2.0\src\gdrive_handler.py:78
2024-07-02 09:11:11,633 - ERROR - Authentication failed: The access_token is expired or invalid and can't be refreshed. - c:\Users\msenthilnathan\chatGPT-GUI\Nool 2.0\src\gdrive_handler.py:78
2024-07-02 13:01:16,267 - ERROR - An error occurred: 'GDriveHandler' object has no attribute 'check_and_download_file' - c:\Users\msenthilnathan\chatGPT-GUI\Nool 2.0\src\gdrive_main.py:83
Traceback (most recent call last):
  File "c:\Users\msenthilnathan\chatGPT-GUI\Nool 2.0\src\gdrive_main.py", line 68, in <module>
    gdrive_handler.check_and_download_file(file_id_to_download, file_name_to_download)
    ^^^^^^^^^^^^^^^^^^^^^^^^^^^^^^^^^^^^^^
AttributeError: 'GDriveHandler' object has no attribute 'check_and_download_file'
2024-07-02 13:05:09,751 - ERROR - An error occurred: module 'datetime' has no attribute 'fromtimestamp' - c:\Users\msenthilnathan\chatGPT-GUI\Nool 2.0\src\gdrive_main.py:83
Traceback (most recent call last):
  File "c:\Users\msenthilnathan\chatGPT-GUI\Nool 2.0\src\gdrive_main.py", line 68, in <module>
    gdrive_handler.check_and_download_file(file_id_to_download, file_name_to_download)
  File "c:\Users\msenthilnathan\chatGPT-GUI\Nool 2.0\src\gdrive_handler.py", line 138, in check_and_download_file
    local_mod_time = datetime.fromtimestamp(os.path.getmtime(local_path), tz=datetime.timezone.utc)
                     ^^^^^^^^^^^^^^^^^^^^^^
AttributeError: module 'datetime' has no attribute 'fromtimestamp'
2024-07-02 13:06:49,688 - ERROR - An error occurred: type object 'datetime.datetime' has no attribute 'timezone' - c:\Users\msenthilnathan\chatGPT-GUI\Nool 2.0\src\gdrive_main.py:83
Traceback (most recent call last):
  File "c:\Users\msenthilnathan\chatGPT-GUI\Nool 2.0\src\gdrive_main.py", line 68, in <module>
    gdrive_handler.check_and_download_file(file_id_to_download, file_name_to_download)
  File "c:\Users\msenthilnathan\chatGPT-GUI\Nool 2.0\src\gdrive_handler.py", line 138, in check_and_download_file
    local_mod_time = datetime.fromtimestamp(os.path.getmtime(local_path), tz=datetime.timezone.utc)
                                                                             ^^^^^^^^^^^^^^^^^
AttributeError: type object 'datetime.datetime' has no attribute 'timezone'. Did you mean: 'astimezone'?
2024-07-02 15:28:29,219 - ERROR - Authentication failed: Unable to find the server at oauth2.googleapis.com - c:\Users\msenthilnathan\chatGPT-GUI\Nool 2.0\src\gdrive_handler.py:80
2024-07-02 15:37:51,072 - ERROR - Authentication failed: Unable to find the server at oauth2.googleapis.com - c:\Users\msenthilnathan\chatGPT-GUI\Nool 2.0\src\gdrive_handler.py:80
2024-07-02 15:38:15,362 - ERROR - Authentication failed: Unable to find the server at oauth2.googleapis.com - c:\Users\msenthilnathan\chatGPT-GUI\Nool 2.0\src\gdrive_handler.py:80
2024-07-02 15:40:50,049 - ERROR - Authentication failed: Unable to find the server at oauth2.googleapis.com - c:\Users\msenthilnathan\chatGPT-GUI\Nool 2.0\src\gdrive_handler.py:89
2024-07-02 15:40:50,049 - ERROR - An error occurred: Unable to find the server at oauth2.googleapis.com - c:\Users\msenthilnathan\chatGPT-GUI\Nool 2.0\src\gdrive_handler.py:26
2024-07-02 15:40:50,049 - ERROR - An error occurred: 'GDriveHandler' object has no attribute 'drive' - c:\Users\msenthilnathan\chatGPT-GUI\Nool 2.0\src\gdrive_main.py:86
Traceback (most recent call last):
  File "c:\Users\msenthilnathan\chatGPT-GUI\Nool 2.0\src\gdrive_main.py", line 54, in <module>
    if gdrive_handler.check_lock_file(folder_id, 'process.lock'):
       ^^^^^^^^^^^^^^^^^^^^^^^^^^^^^^^^^^^^^^^^^^^^^^^^^^^^^^^^^
  File "c:\Users\msenthilnathan\chatGPT-GUI\Nool 2.0\src\gdrive_handler.py", line 122, in check_lock_file
    file_list = self.drive.ListFile({'q': query}).GetList()
                ^^^^^^^^^^
AttributeError: 'GDriveHandler' object has no attribute 'drive'
2024-07-02 15:42:00,880 - ERROR - Authentication failed: Unable to find the server at oauth2.googleapis.com - c:\Users\msenthilnathan\chatGPT-GUI\Nool 2.0\src\gdrive_handler.py:89
2024-07-02 15:42:07,014 - ERROR - An error occurred: Unable to find the server at oauth2.googleapis.com - c:\Users\msenthilnathan\chatGPT-GUI\Nool 2.0\src\gdrive_handler.py:26
2024-07-04 18:06:55,097 - ERROR - Authentication failed: Unable to find the server at oauth2.googleapis.com - c:\Users\msenthilnathan\chatGPT-GUI\Nool 2.0\src\gdrive_handler.py:89
2024-07-04 18:06:55,097 - ERROR - An error occurred: Unable to find the server at oauth2.googleapis.com - c:\Users\msenthilnathan\chatGPT-GUI\Nool 2.0\src\gdrive_handler.py:26
2024-07-04 18:08:16,025 - ERROR - Authentication failed: Unable to find the server at oauth2.googleapis.com - c:\Users\msenthilnathan\chatGPT-GUI\Nool 2.0\src\gdrive_handler.py:89
2024-07-04 18:08:16,026 - ERROR - An error occurred: Unable to find the server at oauth2.googleapis.com - c:\Users\msenthilnathan\chatGPT-GUI\Nool 2.0\src\gdrive_handler.py:26
2024-07-04 18:11:14,582 - ERROR - Authentication failed: Unable to find the server at oauth2.googleapis.com - c:\Users\msenthilnathan\chatGPT-GUI\Nool 2.0\src\gdrive_handler.py:89
2024-07-04 18:11:14,582 - ERROR - An error occurred: Unable to find the server at oauth2.googleapis.com - c:\Users\msenthilnathan\chatGPT-GUI\Nool 2.0\src\gdrive_handler.py:26
2024-07-04 21:21:59,798 - ERROR - Authentication failed: Unable to find the server at oauth2.googleapis.com - c:\Users\msenthilnathan\chatGPT-GUI\Nool 2.0\src\gdrive_handler.py:89
2024-07-04 21:21:59,802 - ERROR - An error occurred: Unable to find the server at oauth2.googleapis.com - c:\Users\msenthilnathan\chatGPT-GUI\Nool 2.0\src\gdrive_handler.py:26
2024-07-04 21:27:49,455 - ERROR - Authentication failed: Unable to find the server at oauth2.googleapis.com - c:\Users\msenthilnathan\chatGPT-GUI\Nool 2.0\src\gdrive_handler.py:89
2024-07-04 21:27:49,455 - ERROR - An error occurred: Unable to find the server at oauth2.googleapis.com - c:\Users\msenthilnathan\chatGPT-GUI\Nool 2.0\src\gdrive_handler.py:26
2024-07-04 21:29:11,392 - ERROR - Authentication failed: Unable to find the server at oauth2.googleapis.com - c:\Users\msenthilnathan\chatGPT-GUI\Nool 2.0\src\gdrive_handler.py:89
2024-07-04 21:29:11,392 - ERROR - An error occurred: Unable to find the server at oauth2.googleapis.com - c:\Users\msenthilnathan\chatGPT-GUI\Nool 2.0\src\gdrive_handler.py:26
2024-07-04 21:37:37,695 - ERROR - Authentication failed: Unable to find the server at oauth2.googleapis.com - c:\Users\msenthilnathan\chatGPT-GUI\Nool 2.0\src\gdrive_handler.py:89
2024-07-04 21:37:37,695 - ERROR - An error occurred: Unable to find the server at oauth2.googleapis.com - c:\Users\msenthilnathan\chatGPT-GUI\Nool 2.0\src\gdrive_handler.py:26
2024-07-04 21:38:14,770 - ERROR - Authentication failed: Unable to find the server at oauth2.googleapis.com - c:\Users\msenthilnathan\chatGPT-GUI\Nool 2.0\src\gdrive_handler.py:89
2024-07-04 21:38:14,770 - ERROR - An error occurred: Unable to find the server at oauth2.googleapis.com - c:\Users\msenthilnathan\chatGPT-GUI\Nool 2.0\src\gdrive_handler.py:26
2024-07-31 21:36:59,058 - ERROR - Authentication failed: Access token refresh failed: invalid_grant: Bad Request - c:\Users\msenthilnathan\chatGPT-GUI\Nool 2.0\src\gdrive_handler.py:89
2024-07-31 21:36:59,058 - ERROR - An error occurred: Access token refresh failed: invalid_grant: Bad Request - c:\Users\msenthilnathan\chatGPT-GUI\Nool 2.0\src\gdrive_handler.py:26
2024-07-31 21:43:48,294 - ERROR - Authentication failed: Access token refresh failed: invalid_grant: Bad Request - c:\Users\msenthilnathan\chatGPT-GUI\Nool 2.0\src\gdrive_handler.py:89
2024-07-31 21:43:48,294 - ERROR - An error occurred: Access token refresh failed: invalid_grant: Bad Request - c:\Users\msenthilnathan\chatGPT-GUI\Nool 2.0\src\gdrive_handler.py:26
2024-07-31 21:47:53,960 - ERROR - Authentication failed: Access token refresh failed: invalid_grant: Bad Request - c:\Users\msenthilnathan\chatGPT-GUI\Nool 2.0\src\gdrive_handler.py:89
2024-07-31 21:47:53,960 - ERROR - An error occurred: Access token refresh failed: invalid_grant: Bad Request - c:\Users\msenthilnathan\chatGPT-GUI\Nool 2.0\src\gdrive_handler.py:26
2024-07-31 21:49:21,610 - ERROR - Authentication failed: Access token refresh failed: invalid_grant: Bad Request - c:\Users\msenthilnathan\chatGPT-GUI\Nool 2.0\src\gdrive_handler.py:89
2024-08-26 22:24:55,096 - ERROR - Authentication failed: Access token refresh failed: invalid_grant: Token has been expired or revoked. - c:\Users\msenthilnathan\Nool 2.0\src\gdrive_handler.py:140
2024-08-26 22:24:55,096 - ERROR - An error occurred: Access token refresh failed: invalid_grant: Token has been expired or revoked. - c:\Users\msenthilnathan\Nool 2.0\src\gdrive_handler.py:31
2024-08-26 22:32:27,688 - ERROR - Authentication failed: Access token refresh failed: invalid_grant: Token has been expired or revoked. - C:\Users\msenthilnathan\Nool 2.0\src\gdrive_handler.py:140
2024-08-26 22:32:27,688 - ERROR - An error occurred: Access token refresh failed: invalid_grant: Token has been expired or revoked. - C:\Users\msenthilnathan\Nool 2.0\src\gdrive_handler.py:31
